#VRML_SIM R2019a utf8
WorldInfo {
}
Viewpoint {
  orientation 0.8256374340201674 -0.5616356557268087 -0.05374214138747535 6.052421521305293
  position 0.17310095904399708 0.38076270463907985 1.467391905032293
}
TexturedBackground {
}
TexturedBackgroundLight {
}
Floor {
}
Robot {
  translation 0 0.075 0
  children [
    Group {
      children [
        Shape {
          appearance PBRAppearance {
            baseColor 0.9372549019607843 0.1607843137254902 0.1607843137254902
          }
          geometry DEF G_BOX Box {
            size 0.25 0.07 0.1
          }
        }
        HingeJoint {
          jointParameters HingeJointParameters {
            axis 0 0 1
            anchor -0.05 0 0.05
          }
          device [
            RotationalMotor {
            }
          ]
          endPoint Solid {
            translation -0.0499976466545348 6.244352856585705e-06 0.06000317076252501
            rotation 0.9999999708596192 0.00017045328350943434 0.00017095741808274235 1.5699997602922906
            children [
              Shape {
                appearance DEF A_W PBRAppearance {
                  baseColor 0 0 0
                }
                geometry DEF G_W Cylinder {
                  height 0.01
                  radius 0.075
                }
              }
            ]
            boundingObject USE G_W
            physics Physics {
            }
          }
        }
        HingeJoint {
          jointParameters HingeJointParameters {
            axis 0 0 1
            anchor -0.05 0 -0.05
          }
          endPoint Solid {
            translation -0.05 0 -0.06
            rotation -0.7228719530004886 -0.4884034850859072 -0.48879256880725935 4.394172730933238
            children [
              Shape {
                appearance USE A_W
                geometry USE G_W
              }
            ]
            name "solid(1)"
            boundingObject USE G_W
            physics Physics {
            }
          }
        }
        HingeJoint {
          jointParameters HingeJointParameters {
            axis 1 1 1
            anchor 0.11 -0.035 0
          }
          endPoint Solid {
            translation 0.11 -0.05 0
            rotation 0.5773502691896258 0.5773502691896258 0.5773502691896258 0
            children [
              Shape {
                appearance USE A_W
                geometry DEF G_S Sphere {
                  radius 0.015
                }
              }
            ]
            name "solid(2)"
            boundingObject USE G_S
            physics Physics {
            }
          }
        }
      ]
    }
  ]
}
