#VRML_SIM R2019a utf8
WorldInfo {
}
Viewpoint {
  orientation 0.7257546682800938 -0.6178414862128471 -0.3025757085159862 5.095977705593531
  position 0.5762175656414669 1.142303020927633 0.8321516514228846
}
TexturedBackground {
}
TexturedBackgroundLight {
}
Floor {
}
Robot {
  translation 0 0.075 0
  children [
    Group {
      children [
        Shape {
          appearance PBRAppearance {
            baseColor 0.9372549019607843 0.1607843137254902 0.1607843137254902
          }
          geometry DEF G_BOX Box {
            size 0.25 0.07 0.1
          }
        }
        HingeJoint {
          jointParameters HingeJointParameters {
            axis 0 0 1
            anchor -0.05 0 0.05
          }
          device [
            DEF motor_right RotationalMotor {
            }
          ]
          endPoint Solid {
            translation -0.0499976466545348 6.244352856585705e-06 0.06000317076252501
            rotation 0.9999999708596192 0.00017045328350943434 0.00017095741808274235 1.5699997602922906
            children [
              Shape {
                appearance DEF A_W PBRAppearance {
                  baseColor 0 0 0
                }
                geometry DEF G_W Cylinder {
                  height 0.01
                  radius 0.075
                }
              }
            ]
            boundingObject USE G_W
            physics Physics {
            }
          }
        }
      ]
    }
  ]
  boundingObject USE G_BOX
  physics Physics {
  }
}
